Celery is not installed; asynchronous task runner disabled. (No module named 'celery')
Creating test database for alias 'default'...

Found 15 test(s).
System check identified no issues (0 silenced).
.......F......E
======================================================================
ERROR: test_sociallink_cache_invalidation_on_save (apps.main.test_cache.SignalCacheInvalidationTestCase.test_sociallink_cache_invalidation_on_save)
Test that SocialLink cache is invalidated on save.
----------------------------------------------------------------------
Traceback (most recent call last):
  File "C:\Users\HP\AAA\apps\main\test_cache.py", line 171, in test_sociallink_cache_invalidation_on_save
    social_link = SocialLink(
        personal_info=personal_info,
    ...<2 lines>...
        is_visible=True
    )
  File "C:\Users\HP\AAA\.venv-1\Lib\site-packages\django\db\models\base.py", line 567, in __init__
    raise TypeError(
    ...<2 lines>...
    )
TypeError: SocialLink() got unexpected keyword arguments: 'personal_info'

======================================================================
FAIL: test_cache_pattern_invalidation (apps.main.test_cache.CacheUtilsTestCase.test_cache_pattern_invalidation)
Test pattern-based cache invalidation.
----------------------------------------------------------------------
Traceback (most recent call last):
  File "C:\Users\HP\AAA\apps\main\test_cache.py", line 84, in test_cache_pattern_invalidation
    self.assertEqual(count, 2)
    ~~~~~~~~~~~~~~~~^^^^^^^^^^
AssertionError: 0 != 2

----------------------------------------------------------------------
Ran 15 tests in 0.050s

FAILED (failures=1, errors=1)
Destroying test database for alias 'default'...

